Workbook

Sheet Arabizi Encoding
A1: 🔤 Arabizi Encoding System — PDF §1
A2: Number | B2: Letter Alternative | C2: Arabic Letter | D2: Sound | E2: Example (Arabizi) | F2: Example (Arabic)
A3: 9 | B3: q / k | C3: ق | D3: q — deep k | E3: 9alet / qalet | F3: قالت
A4: 5 | B4: kh | C4: خ | D4: kh — guttural | E4: 5oya / khoya | F4: خويا
A5: 2 | B5: a / ' | C5: ء | D5: glottal stop | E5: 2enti / aenti | F5: أنتي
A6: 3 | B6: aa | C6: ع | D6: ayn — deep vowel | E6: 3aych / aaych | F6: عايش
A7: 7 | B7: h | C7: ح | D7: heavy h | E7: 7ajet / hajet | F7: حاجة
A8: 6 | B8: t | C8: ط | D8: emphatic t | E8: 6abi3i / tabi3i | F8: طبيعي
A9: 8 | B9: gh | C9: غ | D9: gh — French r | E9: 8ayeb / ghayeb | F9: غايب
A11: ⚠️ Both variants are IDENTICAL — '5oya' and 'khoya' mean the same word. Always normalize before matching. Apply §2 normalization pipeline first.

Sheet Normalization Rules
A1: ⚙️ Text Normalization Rules — Apply in Order Before Intent Detection (PDF §2)
A2: Step | B2: Rule | C2: Description | D2: Example
A3: 1 | B3: Lowercase | C3: Convert all text to lowercase | D3: '3AWEDLY' → '3awedly'
A4: 2 | B4: Remove spaces | C4: Strip all spaces — lazy typing skips them | D4: 'ma fhemtch' → 'mafhemtch'
A5: 3 | B5: Strip repetition | C5: Collapse 3+ repeated letters down to 2 | D5: 'haaaaannnn' → 'haann'
A6: 4 | B6: Fuzzy match | C6: Use rapidfuzz threshold ~80 to catch misspellings | D6: 'mrigl' matches 'mrgl'
A7: 5 | B7: Number → letter | C7: Optionally expand numbers to letter equivalents | D7: '5oya' → 'khoya'

Sheet Raw Collection
A1: 🇹🇳 Tunisian Darija NLP Database — Raw Collection
A2: id | B2: source_platform | C2: source_page | D2: subject | E2: raw_comment | F2: darija_arabizi | G2: variants | H2: intent_category | I2: english_meaning | J2: french_meaning | K2: aggression_level | L2: validated | M2: api_raw_response
A3: 1 | B3: Facebook | C3: Mosaique FM | D3: tech | E3: ya5i fech te7ki 5arreeff barcha | F3: ya5i fech te7ki 5arreeff | G3: ya khi fech te7ki, ya5i chnou hethi, 5arif | H3: hallucination | I3: bro what are you saying you're off topic | J3: frere de quoi tu parles t'es hors sujet | K3: frustrated | L3: yes
A4: 2 | B4: Facebook | C4: Espérance ST | D4: sports | E4: sa7it fhemtk !! jawk behi | F4: sa7it fhemtk | G4: mafhamtch, mafhemtch, zid fesarly, fassarly bilfalla9i, zid watha7li | H4: understood | I4: correct I understood you, your answer was good | J4: correct je t'ai compris, ta réponse était bonne | K4: positive | L4: yes
A5: 3 | B5: YouTube | C5: Tunisian Tech | D5: tech | E5: mafhemt chy zid fassarly bisyassa a3tini example | F5: mafhemt chy zid fassarly bisyassa | G5: mafhamtch, mafhemtch, zid fesarly, fassarly bisyassa | H5: confusion | I5: I didn't understand anything explain slowly give me an example | J5: j'ai rien compris explique doucement donne moi un exemple | K5: neutral | L5: yes
A6: 4 | B6: Facebook | C6: Club Africain | D6: sports | E6: mouch hakka wala mouch kk 3awed miloul | F6: mouch hakka 3awed miloul | G6: mouchhakka, moch kk, 3awed meloul | H6: wrong_answer | I6: that's not right repeat from the beginning | J6: c'est pas ça répète depuis le début | K6: frustrated | L6: yes
A7: 5 | B7: Reddit | C7: r/Tunisia | D7: daily_life | E7: ayast moi la3alayna ouh 3lik ouh | F7: ayast moi la3alayna | G7: ayest, iyest, la3lina, ou3lik | H7: giving_up | I7: I'm done whatever forget it | J7: j'en peux plus c'est bon laisse tomber | K7: aggressive | L7: yes
A8: 6 | B8: null | C8: null | D8: daily_life | E8: 3leh 3malt kk?aleh aamalt haka | F8: 3leh 3malt | G8: 3leh 3amalt, leh 3amalt, leh 3malt | H8: confusion | I8: Why did you do this? | J8: Pourquoi as-tu fait cela? | K8: frustrated | L8: yes
A9: 7 | D9: daily_life | E9: hethaka 3leh | F9: hetha 3leh | G9: hithak 3leh, hethak 3leh, hithaka 3leh | H9: confusion | I9: what's going on with him | J9: qu'est-ce qui se passe avec lui | K9: neutral | L9: yes
A10: 8 | B10: Facebook | C10: Tunisian groups | D10: education | E10: tefhem fia? / tifhim fia? / fhemt? | F10: fhemt | G10: tefhem fia, tifhim fia, tfhem, fhamt | H10: confusion | I10: do you understand? (asking for comprehension check) | J10: est-ce que tu comprends ? | K10: neutral | L10: yes
A11: 9 | B11: Facebook | C11: Tunisian DS groups | D11: education | E11: n7eb nzid data 3la el patients ama menaarefesh kifeh | F11: n7eb nzid data | G11: nheb nzid, n7ib nzid, nheb nzid data, nzid data | H11: simplify | I11: I want to add data but I don't know how | J11: Je veux ajouter des données mais je ne sais pas comment | K11: neutral | L11: review
A12: 10 | B12: Facebook | C12: Tunisian Tech groups | D12: education | E12: Hello guys .. chnoa parcours académique bech ta9ra AI f tunis | F12: chnoa parcours académique | G12: chnoa, chnia, chinhi, chnouwa, shnouwa | H12: confusion | I12: What academic path should I follow to learn AI in Tunisia? | J12: Quel cursus académique pour apprendre l'IA en Tunisie ? | K12: neutral | L12: yes
A13: 11 | B13: Facebook | C13: Tunisian ML groups | D13: education | E13: blhy ena andii projet : la mise en place d'un robot de surveillance ML | F13: blhy ena andii projet | G13: blahi, bl7y, bly, blhy, blahi ena | H13: opening_statement | I13: I have a project about setting up an autonomous surveillance robot using ML | J13: J'ai un projet de mise en place d'un robot de surveillance autonome ML | K13: neutral | L13: review
A14: 12 | B14: Facebook | C14: Tunisian ML groups | D14: education | E14: fih u anta qa3ed tkhadem fi machine learning w mch t3aref estimation w cross validation | F14: fih u anta qa3ed tkhadem fi machine learning | G14: fih u anta qa3ed, fih w anta khadem, fih u tkhadem fi ml | H14: simplify | I14: you're working on ML but you don't understand estimation parameters and cross validation | J14: tu travailles sur le ML mais tu ne comprends pas les paramètres et la cross validation | K14: polite | L14: yes
A15: 13 | B15: Facebook | C15: Tunisian ML groups | D15: education | E15: blhy eli 5dem haja kima hedhi w andou rapport yab3thly merci | F15: blhy eli 5dem haja kima hedhi | G15: blhy eli khadem haja kima hadi, blhy ely 5dem haja kima hedi | H15: understood | I15: someone who did something like this and has a report — thank you | J15: quelqu'un qui a fait quelque chose comme ça et a un rapport — merci | K15: polite | L15: yes
A16: 14 | B16: Facebook | C16: Tunisian Tech groups | D16: education | E16: Cross training maho kimaa esiiir fil edge impulse bedhabet heka walla? | F16: maho kima esir | G16: maho kimaa esiiir, mahou kima esir, maho kimaa asir | H16: confusion | I16: is cross training as easy as it looks in edge impulse or not? | J16: le cross training est-il aussi facile qu'il y paraît dans edge impulse ? | K16: neutral | L16: review
A17: 15 | B17: Facebook | C17: Tunisian Tech groups | D17: education | E17: edge impulse hiya plateforme ta3tik interface mch inti tikhdem from scratch | F17: edge impulse hiya plateforme ta3tik | G17: edge impulse, edgeimpulse, edge impulse hiya, edgeimpulse hiya | H17: understood | I17: Edge Impulse is a platform that gives you an interface so you don't start from scratch | J17: Edge Impulse est une plateforme qui te donne une interface pour ne pas partir de zéro | K17: neutral | L17: yes
A18: 16 | B18: Facebook | C18: Tunisian ML groups | D18: education | E18: akthar video yenjem yfeserlek kifach tta3lem — 9 months self-learning w l9a 5hedma | F18: akthar video yenjem yfeserlek kifach tta3lem | G18: akthar, akther, aktar, kifash, kifaach, kifach | H18: encouragement | I18: this video best explains how to learn — self-taught in 9 months and found a job | J18: cette vidéo explique le mieux comment apprendre — autodidacte en 9 mois et a trouvé un emploi | K18: positive | L18: yes
A19: 17 | B19: Facebook | C19: Tunisian ML groups | D19: education | E19: tfarjo fih alvideo tayara 3al a5er | F19: tfarjo fih alvideo tayara alakhir | G19: tfarjo, tafarja, tfarja, fih, feh, alvideo, tayara, tayyara, alakhir, al7er | H19: simplify | I19: watch the video all the way to the end | J19: regardez la vidéo jusqu'à la fin | K19: neutral | L19: yes
A21: 18 | B21: Edu chatbot | C21: native | D21: education | E21: fassarly bilfalla9i please | F21: fassarly bilfalla9i | G21: fassarly bsahel, fesserly bilfalla9i | H21: simplify | I21: explain in the simplest possible form | J21: explique de la manière la plus simple | K21: polite | L21: yes
A22: 19 | B22: Edu chatbot | C22: native | D22: education | E22: zid watha7li heka mch fahi | F22: zid watha7li | G22: zid wath7li, zidli wtha7, watha7li mazelt | H22: simplify | I22: clarify this more I'm still not getting it | J22: clarifie encore je ne comprends toujours pas | K22: polite | L22: yes
... A98: 95 | B98: Edu chatbot | C98: native | D98: education | E98: tefhem fia / fhemtni wla nzid nfassarlk / kan mafhemtch 7aja 9oli | F98: tefhem fia | G98: tefhem fia, fhemtni, fhemtni wla nzid, kan mafhemtch 9oli | H98: comprehension_check | I98: do you understand me / did you get it or should I explain more / if you didn't understand something tell me | J98: tu me comprends / tu as compris ou j'explique encore / si tu n'as pas compris dis-moi | K98: neutral | L98: yes

Sheet Conversation Threads
A1: 🗣️ Full Conversation Threads — For RAG Training
A2: thread_id | B2: subject | C2: source | D2: context | E2: user_question | F2: ideal_answer | G2: confirmation | H2: language_mix | I2: quality_score | J2: use_in_rag
A3: T001 | B3: tech | C3: Facebook/TunisianDevs | D3: Discussion about how wifi router works | E3: kifeh n3amel router mte3i ych5el mli7? | F3: 5ou bch t3amel router lazem awel tchouf el channel li mch ma7shoch. 3awed el router w t3adel el settings mel interface. normalement 192.168.1.1 fi browser mte3k w tchouf el options. | G3: sa7it fhemtk merci | H3: darija_french | I3: 5 | J3: yes
A4: T002 | B4: health | C4: Facebook/HealthTN | D4: Someone asking about headache remedies | E4: 3andi mal de tete barcha chnou na3mel? | F4: awel 7aja chreb ma bezzef. itha mch 3andek tension khelli rask fi calme w okhod doliprane wella paracetamol. itha dawam akthar men yom, rouh lel doctor. | G4: mrgl jawek behi | H4: darija_french | I4: 4 | J4: yes
A5: T003 | B5: finance | C5: Facebook/TunisianStartups | D5: Discussion about startup funding | E5: fech el farq bin bootstrap w funding? | F5: bootstrap ya3ni t3amel projet mte3k b flous mte3kinti. funding ya3ni t3addi 3la investors yhebbou yaamlou m3ak. bootstrap a7sen lel independence ama funding a7sen lel croissance sari3a. | G5: fhemtk sa7 | H5: darija_french | I5: 5 | J5: yes

Sheet Intent Signals Reference
A1: 📖 Intent Signals Master Reference — Auto-loaded by utils.py
A2: intent | B2: priority | C2: darija_arabizi | D2: variants | E2: normalized_keys | F2: action | G2: color_code
A3: swear | B3: 1 | C3: — | D3: private list | E3: private | F3: 10s timeout, strip from text, continue with cleaned input
A4: giving_up | B4: 2 | C4: ouh 3lik ouh, la3alayna ayy, ayast moi | D4: ou3lik, la3lina ay, la3leyna ayy, ayest, iyest | E4: ouh3lik, la3alayna, ayast, ayest, iyest | F4: Acknowledge + one final 2-sentence attempt
A5: hallucination | B5: 3 | C5: 5arreeff, mouch hakka, heka mouch kk | D5: khareef, 5arif, kharif, mouchhaka, hekamouch | E5: 5arreeff, khareef, mouchhakka, mouchhaka, hekamouch | F5: Apologize + return strictly to original question
A6: wrong_answer | B6: 4 | C6: mouch hakka, mouch kk | D6: mouchhaka, moch kk, mch kk | E6: mouchhakka, mouchhaka, mochkk, mchkk | F6: Re-read context carefully and retry
A7: confusion | B7: 5 | C7: mafhemt chy, chnoa, zid fahamni, zid fassarly, naarech, ya5i fech te7ki, bjaah rabby fech te7ki, yaa wildii | D7: mafhamtch, chnou, shnou, zid fehamni, zid fhamni, ya khi fech te7ki | E7: mafhemtchy, mafhemtch, chnoa, chnou, zidfahamni, zidfassarly, naarech, ya5ifech, bjaahrabbyfech, yawildii | F7: Ask for confirmation + offer to reformulate
A8: half_understood | B8: 6 | C8: fhemt ama mouch barcha, mafhemtch mli7 | D8: fhamt ama moch barcha, mafhamt mli7, mafhamtch mli7 | E8: fhemtamamouch, mafhemtchmli7, mafhamt | F8: Ask what specific part was unclear + clarify
A9: simplify | B9: 7 | C9: a3tini example, het example, fassarly bisyassa | D9: a3tini mithal, hett mithal, fesarly bisyassa | E9: a3tiniexample, hetexample, a3tinimithal, fassarlybisyassa | F9: Re-explain using a concrete real-world example
A10: repeat_all | B10: 8 | C10: 3awed miloul, 3awed meloul | D10: aawed miloul, 3aoud miloul | E10: 3awedmiloul, 3awedmeloul, aawedmiloul | F10: Repeat full answer from the beginning
A11: repeat_part | B11: 9 | C11: lfaza le5ra, 3awidly lfaza hethi | D11: lfaza lakhira, 3awidly hathi, 3awedly hethi | E11: lfazale5ra, lfazalakhira, 3awidlylfaza, 3awedlyhathi | F11: Repeat only the last paragraph/sentence
A12: repeat | B12: 10 | C12: 3awidly, awidly, awedly | D12: 3awedly, 3awidli, awidli | E12: 3awidly, awidly, awedly, 3awedly | F12: Repeat previous full answer
A13: impatience | B13: 11 | C13: na9is mil7dith, fassarly bisyassa | D13: na9es mel7dith, na9es mel hdith | E13: na9ismil7dith, na9esmel7dith | F13: Maximum 2 sentences, direct and to the point
A14: understood | B14: 12 | C14: haaannnnnn, fhemtk, nfhem fik, mrgl, jawek behi, sa7it | D14: hannn, fhamtk, fhimtk, nefhem fik, nifhem fik, mrigl, mregl, jawk bhi, sa7et, sa7 | E14: haann, fhemtk, fhamtk, nfhemfik, mrgl, mrigl, jawekbehi, sa7it, sa7et | F14: Proceed normally — do NOT reformulate
... A44: comprehension_check | B44: 9.5 | C44: tefhem fia, fhemtni wla nzid nfassarlk, kan mafhemtch 7aja 9oli | D44: tefhemni, fhemtni, kan mch fahi 9oli | E44: tefhemfia,fhemtni,kanmafhemtch | F44: Always check after explanation — don't assume understood

Sheet Export Preview
A1: ⚙️ Export Preview — This is how your data will look in ChromaDB
A2: chunk_text | B2: metadata | C2: notes
A3: [INTENT: confusion] User: "mafhemt chy zid fahamni" Action: Reformulate more simply. Variants: mafhamtch, mafhemtch, zid fehamni English: I didn't understand, explain more | B3: {"source": "darija_guide", "intent": "confusion", "aggression": "neutral", "validated": true} | C3: From Intent Signals sheet row 5
A4: [VALIDATED EXCHANGE — tech] User: kifeh n3amel router mte3i? Assistant: 5ou bch t3amel router lazem awel tchouf el channel li mch ma7shoch... Confirmation: sa7it fhemtk | B4: {"source": "feedback_loop", "type": "validated_exchange", "subject": "tech", "quality": 5} | C4: From Conversation Threads sheet

Sheet Stats
A1: 📊 Collection Progress Dashboard
A2: intent_category | B2: collected | C2: target | D2: status
A3: confusion | B3: =COUNTIF('Raw Collection'!H:H,A3) | C3: 50 | D3: =IF(B3>=C3,"✅ Done",IF(B3=0,"🔴 Empty","🟡 In Progress"))
A4: understood | B4: =COUNTIF('Raw Collection'!H:H,A4) | C4: 50 | D4: =IF(B4>=C4,"✅ Done",IF(B4=0,"🔴 Empty","🟡 In Progress"))
A5: half_understood | B5: =COUNTIF('Raw Collection'!H:H,A5) | C5: 30 | D5: =IF(B5>=C5,"✅ Done",IF(B5=0,"🔴 Empty","🟡 In Progress"))
A6: repeat | B6: =COUNTIF('Raw Collection'!H:H,A6) | C6: 30 | D6: =IF(B6>=C6,"✅ Done",IF(B6=0,"🔴 Empty","🟡 In Progress"))
A7: repeat_all | B7: =COUNTIF('Raw Collection'!H:H,A7) | C7: 20 | D7: =IF(B7>=C7,"✅ Done",IF(B7=0,"🔴 Empty","🟡 In Progress"))
A8: repeat_part | B8: =COUNTIF('Raw Collection'!H:H,A8) | C8: 20 | D8: =IF(B8>=C8,"✅ Done",IF(B8=0,"🔴 Empty","🟡 In Progress"))
A9: simplify | B9: =COUNTIF('Raw Collection'!H:H,A9) | C9: 30 | D9: =IF(B9>=C9,"✅ Done",IF(B9=0,"🔴 Empty","🟡 In Progress"))
A10: hallucination | B10: =COUNTIF('Raw Collection'!H:H,A10) | C10: 30 | D10: =IF(B10>=C10,"✅ Done",IF(B10=0,"🔴 Empty","🟡 In Progress"))
A11: wrong_answer | B11: =COUNTIF('Raw Collection'!H:H,A11) | C11: 30 | D11: =IF(B11>=C11,"✅ Done",IF(B11=0,"🔴 Empty","🟡 In Progress"))
A12: giving_up | B12: =COUNTIF('Raw Collection'!H:H,A12) | C12: 20 | D12: =IF(B12>=C12,"✅ Done",IF(B12=0,"🔴 Empty","🟡 In Progress"))
A13: impatience | B13: =COUNTIF('Raw Collection'!H:H,A13) | C13: 20 | D13: =IF(B13>=C13,"✅ Done",IF(B13=0,"🔴 Empty","🟡 In Progress"))
A14: pushback | B14: =COUNTIF('Raw Collection'!H:H,A14) | C14: 20 | D14: =IF(B14>=C14,"✅ Done",IF(B14=0,"🔴 Empty","🟡 In Progress"))
A15: encouragement | B15: =COUNTIF('Raw Collection'!H:H,A15) | C15: 30 | D15: =IF(B15>=C15,"✅ Done",IF(B15=0,"🔴 Empty","🟡 In Progress"))
A16: TOTAL | B16: =SUM(B3:B30) | C16: =SUM(C3:C15) | D16: =IF(B16>=C16,"✅ Complete","⬜ In Progress")
A17: continue_deeper | B17: =COUNTIF('Raw Collection'!H:H,A17) | C17: 25 | D17: =IF(B17>=C17,"✅ Done",IF(B17=0,"🔴 Empty","🟡 In Progress"))
A18: clarification_question | B18: =COUNTIF('Raw Collection'!H:H,A18) | C18: 30 | D18: =IF(B18>=C18,"✅ Done",IF(B18=0,"🔴 Empty","🟡 In Progress"))
A19: why_question | B19: =COUNTIF('Raw Collection'!H:H,A19) | C19: 25 | D19: =IF(B19>=C19,"✅ Done",IF(B19=0,"🔴 Empty","🟡 In Progress"))
A20: compare_question | B20: =COUNTIF('Raw Collection'!H:H,A20) | C20: 25 | D20: =IF(B20>=C20,"✅ Done",IF(B20=0,"🔴 Empty","🟡 In Progress"))
A21: definition_question | B21: =COUNTIF('Raw Collection'!H:H,A21) | C21: 25 | D21: =IF(B21>=C21,"✅ Done",IF(B21=0,"🔴 Empty","🟡 In Progress"))
A22: consequence_question | B22: =COUNTIF('Raw Collection'!H:H,A22) | C22: 20 | D22: =IF(B22>=C22,"✅ Done",IF(B22=0,"🔴 Empty","🟡 In Progress"))
A23: source_check | B23: =COUNTIF('Raw Collection'!H:H,A23) | C23: 20 | D23: =IF(B23>=C23,"✅ Done",IF(B23=0,"🔴 Empty","🟡 In Progress"))
A24: pdf_reference | B24: =COUNTIF('Raw Collection'!H:H,A24) | C24: 20 | D24: =IF(B24>=C24,"✅ Done",IF(B24=0,"🔴 Empty","🟡 In Progress"))
A25: pdf_mismatch | B25: =COUNTIF('Raw Collection'!H:H,A25) | C25: 20 | D25: =IF(B25>=C25,"✅ Done",IF(B25=0,"🔴 Empty","🟡 In Progress"))
A26: pdf_confusion | B26: =COUNTIF('Raw Collection'!H:H,A26) | C26: 20 | D26: =IF(B26>=C26,"✅ Done",IF(B26=0,"🔴 Empty","🟡 In Progress"))
A27: persistent_confusion | B27: =COUNTIF('Raw Collection'!H:H,A27) | C27: 30 | D27: =IF(B27>=C27,"✅ Done",IF(B27=0,"🔴 Empty","🟡 In Progress"))
A28: closing_thanks | B28: =COUNTIF('Raw Collection'!H:H,A28) | C28: 20 | D28: =IF(B28>=C28,"✅ Done",IF(B28=0,"🔴 Empty","🟡 In Progress"))
... A44: comprehension_check | B44: =COUNTIF('Raw Collection'!H:H,A44) | C44: 25 | D44: =IF(B44>=C44,"✅ Done",IF(B44=0,"🔴 Empty","🟡 In Progress"))

Sheet Bot Behavior Guide
A1: 🤖 Bot Behavior Guide — Built from Native Tunisian Speaker
A2: EXPLANATION STRUCTURE — always in this order
A3: Step | B3: What the bot does | C3: Darija connector | D3: Example
A4: 1 | B4: Short definition first (ta3rif 9sir) | C4: rit milloul... | D4: "rit milloul, el machine learning ya3ni..."
A5: 2 | B5: Real Tunisian life example (mitha reel tounsi) | C5: ...mba3d... | D5: "mba3d, 9abbel kima 3andek 7anout..."
A6: 3 | B6: How to use it in practice (kifeh nesta3mlouha) | C6: ...fil le5er | D6: "fil le5er, nesta3mlouha bch..."
A8: LANGUAGE MIX RULES
A9: Rule | B9: Description | C9: Example | D9: Note
A10: Default | B10: Darija base + French/English technical terms | C10: "el model ya3ni...", "le dataset hedha" | D10: Adapt to user's dominant language
A11: French-heavy user | B11: Mirror their French ratio in responses | C11: If they write in French → more French | D11: Follow the student
A12: English-heavy user | B12: Mirror their English ratio in responses | C12: If they write in English → more English | D12: Follow the student
A13: fassarly b darija request | B13: Go full Darija — no French/English terms | C13: Honour the explicit request | D13: User-controlled
A15: TONE & PERSONALITY
A16: Trait | B16: Description | C16: Tunisian phrasing | D16: Avoid
A17: Warm & respectful | B17: Friendly talks naturally (ykollem behi btorbia) | C17: "3andi, nfasserlek..." | D17: Cold/robotic
A18: Direct answers | B18: Short and to the point (jawbek bfacon 9sira) | C18: Get to the point fast | D18: Long intros
A19: Uses emojis | B19: Light emoji use for warmth — max 1-2 per message | C19: 😊 ✅ 💡 | D19: Overuse
A20: Re-asks when unsure | B20: Confirms before answering ambiguous questions | C20: "ya3ni tsaleni 3la...?" | D20: Guessing wrong
A21: Gender aware | B21: Adapts fahm/fahma, fahi/faha based on context | C21: "mazelt mouch fahma?" for girls | D21: Always masculine default
A23: STEP CONNECTORS — use these, not the French equivalents
A24: Position | B24: Correct Tunisian Darija | C24: Do NOT use | D24: Note
A25: First | B25: rit milloul | C25: lawel, premièrement | D25: Native confirmed ✓
A26: Then | B26: mba3d | C26: ba3dha, ensuite | D26: Most natural connector
A27: Finally | B27: fil le5er | C27: lakhir, finalement | D27: Native confirmed ✓
A28: Slowly / step by step | B28: bichwaya bichwaya | C28: khoutha khoutha | D28: Corrected by native speaker
A30: ANALOGY BANK — Tunisian real-life comparisons that land
A31: Concept | B31: Tunisian analogy | C31: Darija phrasing | D31: Domain
A32: Data storage | B32: 7anout (corner shop) storing products | C32: "9abbel kima 3andek 7anout fih kol 7aja fi blaasha" | D32: CS/Tech
A33: Algorithm | B33: Recipe steps (wa9fet tayyeb) | C33: "kima wa9fet el couscous, kol 5outha w 5outha" | D33: CS/Math
A34: Variable | B34: Jar with a label (bocal b 3onwan) | C34: "9abbel kima bocal mektoub 3liha isem" | D34: Programming
A35: Function | B35: Tool you call when needed | C35: "kima t3ayet l5ouya bch y3awnek" (note: 5ouya not 5ou) | D35: Programming
A36: Loop | B36: Repeat until done (3amel l7aja 7atta tkamel) | C36: "kima t8sel 7awajej wa7da wa7da" | D36: Programming
A38: NATIVE CORRECTIONS LOG — 13 errors fixed in this version
A39: Wrong (old database) | B39: Correct (native Tunisian) | C39: Category | D39: Confirmed by
A40: chnou (marked common) | B40: chnoa / chnia / chinhi — more frustration = more variants | C40: vocabulary | D40: Native speaker
A41: 3aslema = goodbye/thanks | B41: 3aslema = casual HELLO only — never use as thanks | C41: semantics | D41: Native speaker
A42: barcha 3lik (used freely) | B42: Too excessive/formal in this context — avoid | C42: pragmatics | D42: Native speaker
A43: ki ya3ni | B43: kifeh maaneha (authentic Tunisian form) | C43: vocabulary | D43: Native speaker
A44: sa3eb | B44: s3ib (correct Tunisian pronunciation) | C44: phonology | D44: Native speaker
A45: zidi explain | B45: zid fassarly / zid watha7li | C45: vocabulary | D45: Native speaker
...

Sheet Swearing Policy
A1: 🚫 Swearing Detection Policy — PDF §12
A2: Signal Type | B2: Action | C2: Duration | D2: Notes
A3: Swear word detected | B3: Pause response — show polite warning | C3: 10 second cooldown | D3: Strip from text, treat as punctuation not meaning
A4: Swear + confusion signal | B4: Apply timeout THEN reformulate | C4: 10s then respond | D4: Swear always processed first (Priority 1 in §13)
A5: Swear + giving up signal | B5: Apply timeout THEN acknowledge | C5: 10s then respond | D5: Never repeat swear words back to the user
A7: 📌 Implementation Note | B7: Maintain a private SWEAR_WORDS list in your codebase. Strip swear words from the sentence before intent detection — treat them as punctuation, not meaning. Never log or repeat swear words back to the user. Users frequently swear as emphasis or frustration markers — not literal insults.

Sheet Priority Order
A1: 📋 Intent Detection Priority Order — PDF §13 (when multiple signals appear in one message)
A2: Priority | B2: Signal Type | C2: Bot Action
A3: 1 | B3: Swear word ← HIGHEST | C3: 10s timeout — strip swear from text then continue with cleaned input
A4: 2 | B4: Giving up | C4: Acknowledge + one last simplified 2-sentence attempt then stop
A5: 3 | B5: Hallucination flag | C5: Apologize + retry strictly with original question
A6: 4 | B6: Off topic / wrong answer | C6: Acknowledge + correct course
A7: 5 | B7: Confusion signal | C7: Ask to confirm + offer to reformulate
A8: 6 | B8: Half understood | C8: Ask what specific part was unclear
A9: 7 | B9: Simplify request | C9: Re-explain using concrete real-world example
A10: 8 | B10: Repeat request | C10: Repeat full or partial previous answer
A11: 9 | B11: Impatience | C11: Give maximum 2 sentences, direct and to the point
A12: 10 | B12: Understood / praise ← LOWEST | C12: Proceed normally — do NOT reformulate

Sheet Sample Dialogues
A1: 💬 Sample Dialogues for RAG Context — PDF §14 (chunk each row separately for best retrieval)
A2: User Input (Arabizi) | B2: Bot Action | C2: Intent Triggered | D2: RAG Chunk Notes
A3: mafhemt chy | B3: Reformulate in simpler terms | C3: confusion | D3: Trigger: didn't understand anything
A4: zid fassarly bisyassa | B4: Slow down — use shorter sentences | C4: simplify | D4: Trigger: explain slowly / bichwaya bichwaya
A5: 5arreeff | B5: Apologize + reset to original question | C5: hallucination | D5: Trigger: off topic / hallucinating
A6: a3tini example | B6: Provide a concrete real-world example | C6: simplify | D6: Trigger: give example / a3tini mitha
A7: haaannnnnn fhemtk | B7: Proceed normally — do NOT reformulate | C7: understood | D7: Both understood signals together = strong confirmation
A8: ama mouch kk | B8: Acknowledge pushback — invite correction | C8: pushback | D8: Partial agreement + disagreement
A9: ayast moi | B9: One final simplified attempt then stop | C9: giving_up | D9: Trigger: exhausted / done trying
A10: na9is mil7dith | B10: Give 1–2 sentence direct answer only | C10: impatience | D10: Trigger: too long / get to the point
A11: 3awed miloul | B11: Repeat full answer from the beginning | C11: repeat_all | D11: Trigger: rit milloul = from the start
A12: lfaza le5ra 3awidha | B12: Repeat only the last paragraph/sentence | C12: repeat_part | D12: Trigger: last part only
A14: 📌 RAG Strategy: chunk this sheet by section for best retrieval. Each row = one RAG chunk. Similarity search returns focused results per intent.

Sheet User Suggestions
A1: timestamp | B1: context_question | C1: context_answer | D1: suggestion | E1: status | F1: reviewer_note
